<mujoco model="jackal">
    <compiler angle="radian" meshdir="mujoco_meshes/" />
    <option timestep="0.01" integrator="RK4" gravity="0 0 -9.81"/>
    <size nconmax="1000" njmax="5000" />
    
    <default>
        <joint armature="1" damping="1" limited="false" />
        <geom condim="3" friction="1 0.5 0.5" solimp="0.9 0.95 0.001" solref="0.02 1"/>
    </default>

    <asset>
        <material name="dark_grey" rgba="0.2 0.2 0.2 1.0" />
        <material name="light_grey" rgba="0.4 0.4 0.4 1.0" />
        <material name="yellow" rgba="0.8 0.8 0.0 1.0" />
        <material name="black" rgba="0.15 0.15 0.15 1.0" />
        <material name="white" rgba="1.0 1.0 1.0 1.0" />
        <material name="green" rgba="0.0 1.0 0.0 1.0" />
        <material name="floor" rgba="0.5 0.5 0.5 1.0" />
        <material name="obstacleColor" rgba="0.8 0.1 0.1 1.0" />
        <material name="wallColor" rgba="1.0 0.5 0.0 1.0" />
        
        <mesh name="jackal-wheel" file="jackal-wheel.stl" />
        <mesh name="jackal-base" file="jackal-base.stl" />
        <mesh name="jackal-fender" file="jackal-fender.stl" />
        <mesh name="vlp16_base_1" file="VLP16_base_1.stl" />
        <mesh name="vlp16_base_2" file="VLP16_base_2.stl" />
        <mesh name="vlp16_scan" file="VLP16_scan.stl" />
    </asset>

    <equality>
        <!-- Left side wheels move together -->
        <joint joint1="front_left_wheel" joint2="rear_left_wheel"/>
        <!-- Right side wheels move together -->
        <joint joint1="front_right_wheel" joint2="rear_right_wheel"/>
    </equality>
    
    <worldbody>
        <!-- Add a floor/plane -->
        <geom name="floor" type="plane" size="20 20 0.1" pos="0 0 0" material="floor" group="2"/>

         <!-- Add a light above the robot -->
        <light name="spotlight" mode="targetbody" target="chassis_link" pos="0 0 2.0" dir="0 0 -1" 
                 cutoff="30" exponent="1" diffuse="1.0 1.0 1.0" specular="0.5 0.5 0.5"/>

        <body name="base_link" pos="0 0 0.067">
            <freejoint name="root_joint"/>
            <body name="chassis_link" pos="0 0 0">
                <geom type="mesh" mesh="jackal-base" material="dark_grey" pos="0 0 -0.067" euler="0 1.5708 1.5708" group="2"/>
                <geom type="box" size="0.21 0.155 0.092" pos="0 0 0.092" material="dark_grey" rgba="0.2 0.2 0.2 0.2" group="2"/>
                <inertial pos="0.012 0.002 0.067" mass="16.523" diaginertia="0.3136 0.3922 0.4485" />
                
                <!-- Wheels -->
                <body name="front_left_wheel_link" pos="0.131 0.187795 0.0345">
                    <joint name="front_left_wheel" type="hinge" axis="0 1 0" damping="0.1"/>
                    <geom type="mesh" mesh="jackal-wheel" material="black" euler="1.5708 0 0" group="2"/>
                    <geom type="cylinder" size="0.098 0.02" euler="1.5708 0 0" material="black" friction="1 0.005 0.0001" group="2"/>
                    <inertial pos="0 0 0" mass="0.477" diaginertia="0.0013 0.0024 0.0013" />
                </body>
                
                <body name="front_right_wheel_link" pos="0.131 -0.187795 0.0345">
                    <joint name="front_right_wheel" type="hinge" axis="0 1 0" damping="0.1"/>
                    <geom type="mesh" mesh="jackal-wheel" material="black" euler="1.5708 0 0" group="2"/>
                    <geom type="cylinder" size="0.098 0.02" euler="1.5708 0 0" material="black" friction="1 0.005 0.0001" group="2"/>
                    <inertial pos="0 0 0" mass="0.477" diaginertia="0.0013 0.0024 0.0013" />
                </body>
                
                <body name="rear_left_wheel_link" pos="-0.131 0.187795 0.0345">
                    <joint name="rear_left_wheel" type="hinge" axis="0 1 0" damping="0.1"/>
                    <geom type="mesh" mesh="jackal-wheel" material="black" euler="1.5708 0 0" />
                    <geom type="cylinder" size="0.098 0.02" euler="1.5708 0 0" material="black" friction="1 0.005 0.0001" group="2"/>
                    <inertial pos="0 0 0" mass="0.477" diaginertia="0.0013 0.0024 0.0013" />
                </body>
                
                <body name="rear_right_wheel_link" pos="-0.131 -0.187795 0.0345">
                    <joint name="rear_right_wheel" type="hinge" axis="0 1 0" damping="0.1"/>
                    <geom type="mesh" mesh="jackal-wheel" material="black" euler="1.5708 0 0" group="2"/>
                    <geom type="cylinder" size="0.098 0.02" euler="1.5708 0 0" material="black" friction="1 0.005 0.0001" group="2"/>
                    <inertial pos="0 0 0" mass="0.477" diaginertia="0.0013 0.0024 0.0013" />
                </body>
                
                <!-- Fenders -->
                <body name="front_fender_link" pos="0 0 0">
                    <geom type="mesh" mesh="jackal-fender" material="yellow" group="2"/>
                </body>
                
                <body name="rear_fender_link" pos="0 0 0" quat="0 0 0 1">
                  <geom type="mesh" mesh="jackal-fender" material="yellow" group="2"/>
                </body>
                
                <!-- IMU Link -->
                <body name="imu_link">
                    <inertial pos="0 0 0" mass="0.001" diaginertia="1e-09 1e-09 1e-09" />
                </body>
                
                <!-- NAVSAT Link -->
                <body name="navsat_link" pos="-0.180 0.126 0.1815">
                    <geom type="cylinder" size="0.026 0.008" pos="0 0 0.008" material="black" group="2"/>
                </body>
                
                <!-- Mounts -->
                <body name="mid_mount" pos="0 0 0.184">
                    <!-- VLP16 Mount -->
                    <body name="mid_vlp16_mount" pos="0 0 0">
                        <body name="mid_vlp16_leg1" pos="0.05 0.05 0">
                            <geom type="cylinder" size="0.003 0.05" pos="0 0 0.05" material="white" group="2"/>
                        </body>
                        
                        <body name="mid_vlp16_leg2" pos="0.05 -0.05 0">
                            <geom type="cylinder" size="0.003 0.05" pos="0 0 0.05" material="white" group="2"/>
                        </body>
                        
                        <body name="mid_vlp16_leg3" pos="-0.05 0.05 0">
                            <geom type="cylinder" size="0.003 0.05" pos="0 0 0.05" material="white" group="2"/>
                        </body>
                        
                        <body name="mid_vlp16_leg4" pos="-0.05 -0.05 0">
                            <geom type="cylinder" size="0.003 0.05" pos="0 0 0.05" material="white" group="2"/>
                        </body>
                        
                        <body name="mid_vlp16_plate" pos="0 0 0.1">
                            <geom type="box" size="0.05 0.05 0.001" pos="0 0 -0.001" material="black" group="2"/>
                            
                            <!-- Velodyne LiDAR -->
                            <body name="velodyne_base_link" pos="0 0 0">
                                <geom type="mesh" mesh="vlp16_base_1" group="2"/>
                                <geom type="mesh" mesh="vlp16_base_2" group="2"/>
                                <geom type="cylinder" size="0.0516 0.03585" pos="0 0 0.03585" group="2"/>
                                <inertial pos="0 0 0" mass="0.1" diaginertia="0.1 0.1 0.1" />
                                
                                <body name="velodyne" pos="0 0 0.0377">
                                    <geom type="mesh" mesh="vlp16_scan" pos="0 0 -0.0377" group="2"/>
                                    <inertial pos="0 0 0" mass="0.1" diaginertia="0.1 0.1 0.1" />
                                </body>
                            </body>
                        </body>
                    </body>
                    
                    <body name="rear_mount" pos="-0.12 0 0" />
                    <body name="front_mount" pos="0.12 0 0" />
                </body>
            </body>
        </body>

        <!-- Walls Enclosing the Robot [-5, 5] 10x10 Arena -->
        <body name="wall1" pos="5 0 0.5">
            <geom type="box" size="0.1 5 0.5" material="wallColor" group="1"/>
        </body>
        <body name="wall2" pos="-5 0 0.5">
            <geom type="box" size="0.1 5 0.5" material="wallColor" group="1"/>
        </body>
        <body name="wall3" pos="0 5 0.5">
            <geom type="box" size="5 0.1 0.5" material="wallColor" group="1"/>
        </body>
        <body name="wall4" pos="0 -5 0.5">
            <geom type="box" size="5 0.1 0.5" material="wallColor" group="1"/>
        </body>
    
        <!--START_OBSTACLES-->
		<body name="obstacle1" pos="1.901 -4.171 0.085">
			<geom type="box" size="0.50 0.40 0.17" material="obstacleColor" group="1"/>
		</body>
		<body name="obstacle2" pos="-3.427 0.600 0.100">
			<geom type="box" size="0.37 0.33 0.20" material="obstacleColor" group="1"/>
		</body>
		<body name="obstacle3" pos="-0.438 -4.861 0.090">
			<geom type="box" size="1.62 1.45 0.18" material="obstacleColor" group="1"/>
		</body>
		<body name="obstacle4" pos="-1.624 -4.968 0.850">
			<geom type="sphere" size="0.85" material="obstacleColor" group="1"/>
		</body>
		<body name="obstacle5" pos="0.722 -2.816 0.115">
			<geom type="box" size="0.74 0.30 0.23" material="obstacleColor" group="1"/>
		</body>
		<!--END_OBSTACLES-->

        <!--START_GOAL-->
		<body name="goal" pos="4.433 2.520 0.125" euler="0 0 -2.046">
			<geom name="goal_geom" type="box" size="0.25 0.25 0.25" material="green" group="2"/>
		</body>
		<!--END_GOAL-->

    </worldbody>
    
    <actuator>
        <!-- Keep all four actuators, but we'll only need to control two -->
        <motor name="left_actuator" joint="front_left_wheel" gear="20" ctrlrange="-1 1" />
        <motor name="right_actuator" joint="front_right_wheel" gear="20" ctrlrange="-1 1" />
        <!-- These actuators won't need direct control due to the equality constraints -->
        <motor name="rear_left_actuator" joint="rear_left_wheel" gear="20" ctrlrange="-1 1" />
        <motor name="rear_right_actuator" joint="rear_right_wheel" gear="20" ctrlrange="-1 1" />
    </actuator>
</mujoco>