<?xml version="1.0" ?>
<!-- =================================================================================== -->
<!-- |    This document was autogenerated by xacro from jackal.urdf.xacro              | -->
<!-- |    EDITING THIS FILE BY HAND IS NOT RECOMMENDED                                 | -->
<!-- =================================================================================== -->
<robot name="jackal">
  <material name="dark_grey">
    <color rgba="0.2 0.2 0.2 1.0"/>
  </material>
  <material name="light_grey">
    <color rgba="0.4 0.4 0.4 1.0"/>
  </material>
  <material name="yellow">
    <color rgba="0.8 0.8 0.0 1.0"/>
  </material>
  <material name="black">
    <color rgba="0.15 0.15 0.15 1.0"/>
  </material>
  <link name="front_left_wheel_link">
    <visual>
      <origin rpy="1.5707963267948966 0 0" xyz="0 0 0"/>
      <geometry>
        <mesh filename="../meshes/jackal-wheel.stl"/>
      </geometry>
      <material name="black"/>
    </visual>
    <collision>
      <origin rpy="1.5707963267948966 0 0" xyz="0 0 0"/>
      <geometry>
        <cylinder length="0.04" radius="0.098"/>
      </geometry>
    </collision>
    <inertial>
      <origin rpy="0 0 0" xyz="0 0 0"/>
      <mass value="0.477"/>
      <inertia ixx="0.0013" ixy="0" ixz="0" iyy="0.0024" iyz="0" izz="0.0013"/>
    </inertial>
  </link>
  <gazebo reference="front_left_wheel_link">
    <material>Gazebo/DarkGrey</material>
    <selfCollide>false</selfCollide>
    <mu1 value="0.5"/>
    <mu2 value="0.5"/>
    <kp value="10000000.0"/>
    <kd value="1"/>
    <fdir1 value="1 0 0"/>
  </gazebo>
  <joint name="front_left_wheel" type="continuous">
    <parent link="chassis_link"/>
    <child link="front_left_wheel_link"/>
    <origin rpy="0 0 0" xyz="0.131 0.187795 0.0345"/>
    <axis xyz="0 1 0"/>
  </joint>
  <!-- In reality, Jackal has only two motors, one per side. However, it's more
         straightforward for Gazebo to simulate as if there's an actuator per wheel. -->
  <transmission name="front_left_wheel_trans">
    <type>transmission_interface/SimpleTransmission</type>
    <joint name="front_left_wheel">
      <hardwareInterface>hardware_interface/VelocityJointInterface</hardwareInterface>
    </joint>
    <actuator name="front_left_actuator">
      <mechanicalReduction>1</mechanicalReduction>
    </actuator>
  </transmission>
  <link name="front_right_wheel_link">
    <visual>
      <origin rpy="1.5707963267948966 0 0" xyz="0 0 0"/>
      <geometry>
        <mesh filename="../meshes/jackal-wheel.stl"/>
      </geometry>
      <material name="black"/>
    </visual>
    <collision>
      <origin rpy="1.5707963267948966 0 0" xyz="0 0 0"/>
      <geometry>
        <cylinder length="0.04" radius="0.098"/>
      </geometry>
    </collision>
    <inertial>
      <origin rpy="0 0 0" xyz="0 0 0"/>
      <mass value="0.477"/>
      <inertia ixx="0.0013" ixy="0" ixz="0" iyy="0.0024" iyz="0" izz="0.0013"/>
    </inertial>
  </link>
  <gazebo reference="front_right_wheel_link">
    <material>Gazebo/DarkGrey</material>
    <selfCollide>false</selfCollide>
    <mu1 value="0.5"/>
    <mu2 value="0.5"/>
    <kp value="10000000.0"/>
    <kd value="1"/>
    <fdir1 value="1 0 0"/>
  </gazebo>
  <joint name="front_right_wheel" type="continuous">
    <parent link="chassis_link"/>
    <child link="front_right_wheel_link"/>
    <origin rpy="0 0 0" xyz="0.131 -0.187795 0.0345"/>
    <axis xyz="0 1 0"/>
  </joint>
  <!-- In reality, Jackal has only two motors, one per side. However, it's more
         straightforward for Gazebo to simulate as if there's an actuator per wheel. -->
  <transmission name="front_right_wheel_trans">
    <type>transmission_interface/SimpleTransmission</type>
    <joint name="front_right_wheel">
      <hardwareInterface>hardware_interface/VelocityJointInterface</hardwareInterface>
    </joint>
    <actuator name="front_right_actuator">
      <mechanicalReduction>1</mechanicalReduction>
    </actuator>
  </transmission>
  <link name="rear_left_wheel_link">
    <visual>
      <origin rpy="1.5707963267948966 0 0" xyz="0 0 0"/>
      <geometry>
        <mesh filename="../meshes/jackal-wheel.stl"/>
      </geometry>
      <material name="black"/>
    </visual>
    <collision>
      <origin rpy="1.5707963267948966 0 0" xyz="0 0 0"/>
      <geometry>
        <cylinder length="0.04" radius="0.098"/>
      </geometry>
    </collision>
    <inertial>
      <origin rpy="0 0 0" xyz="0 0 0"/>
      <mass value="0.477"/>
      <inertia ixx="0.0013" ixy="0" ixz="0" iyy="0.0024" iyz="0" izz="0.0013"/>
    </inertial>
  </link>
  <gazebo reference="rear_left_wheel_link">
    <material>Gazebo/DarkGrey</material>
    <selfCollide>false</selfCollide>
    <mu1 value="0.5"/>
    <mu2 value="0.5"/>
    <kp value="10000000.0"/>
    <kd value="1"/>
    <fdir1 value="1 0 0"/>
  </gazebo>
  <joint name="rear_left_wheel" type="continuous">
    <parent link="chassis_link"/>
    <child link="rear_left_wheel_link"/>
    <origin rpy="0 0 0" xyz="-0.131 0.187795 0.0345"/>
    <axis xyz="0 1 0"/>
  </joint>
  <!-- In reality, Jackal has only two motors, one per side. However, it's more
         straightforward for Gazebo to simulate as if there's an actuator per wheel. -->
  <transmission name="rear_left_wheel_trans">
    <type>transmission_interface/SimpleTransmission</type>
    <joint name="rear_left_wheel">
      <hardwareInterface>hardware_interface/VelocityJointInterface</hardwareInterface>
    </joint>
    <actuator name="rear_left_actuator">
      <mechanicalReduction>1</mechanicalReduction>
    </actuator>
  </transmission>
  <link name="rear_right_wheel_link">
    <visual>
      <origin rpy="1.5707963267948966 0 0" xyz="0 0 0"/>
      <geometry>
        <mesh filename="../meshes/jackal-wheel.stl"/>
      </geometry>
      <material name="black"/>
    </visual>
    <collision>
      <origin rpy="1.5707963267948966 0 0" xyz="0 0 0"/>
      <geometry>
        <cylinder length="0.04" radius="0.098"/>
      </geometry>
    </collision>
    <inertial>
      <origin rpy="0 0 0" xyz="0 0 0"/>
      <mass value="0.477"/>
      <inertia ixx="0.0013" ixy="0" ixz="0" iyy="0.0024" iyz="0" izz="0.0013"/>
    </inertial>
  </link>
  <gazebo reference="rear_right_wheel_link">
    <material>Gazebo/DarkGrey</material>
    <selfCollide>false</selfCollide>
    <mu1 value="0.5"/>
    <mu2 value="0.5"/>
    <kp value="10000000.0"/>
    <kd value="1"/>
    <fdir1 value="1 0 0"/>
  </gazebo>
  <joint name="rear_right_wheel" type="continuous">
    <parent link="chassis_link"/>
    <child link="rear_right_wheel_link"/>
    <origin rpy="0 0 0" xyz="-0.131 -0.187795 0.0345"/>
    <axis xyz="0 1 0"/>
  </joint>
  <!-- In reality, Jackal has only two motors, one per side. However, it's more
         straightforward for Gazebo to simulate as if there's an actuator per wheel. -->
  <transmission name="rear_right_wheel_trans">
    <type>transmission_interface/SimpleTransmission</type>
    <joint name="rear_right_wheel">
      <hardwareInterface>hardware_interface/VelocityJointInterface</hardwareInterface>
    </joint>
    <actuator name="rear_right_actuator">
      <mechanicalReduction>1</mechanicalReduction>
    </actuator>
  </transmission>
  <link name="base_link"/>
  <joint name="base_link_joint" type="fixed">
    <origin rpy="0 0 0" xyz="0 0 0"/>
    <parent link="base_link"/>
    <child link="chassis_link"/>
  </joint>
  <link name="chassis_link">
    <visual>
      <origin rpy="1.5707963267948966 0 1.5707963267948966" xyz="0 0 -0.0655"/>
      <geometry>
        <mesh filename="../meshes/jackal-base.stl"/>
      </geometry>
      <material name="dark_grey"/>
    </visual>
    <collision>
      <origin xyz="0 0 0.092"/>
      <geometry>
        <box size="0.42 0.31 0.184"/>
      </geometry>
    </collision>
    <inertial>
      <!-- Center of mass -->
      <origin rpy="0 0 0" xyz="0.012  0.002 0.067"/>
      <mass value="16.523"/>
      <!-- Moments of inertia: ( chassis without wheels ) -->
      <inertia ixx="0.3136" ixy="-0.0008" ixz="0.0164" iyy="0.3922" iyz="-0.0009" izz="0.4485"/>
    </inertial>
  </link>
  <link name="front_fender_link">
    <visual>
      <geometry>
        <mesh filename="../meshes/jackal-fender.stl"/>
      </geometry>
      <material name="yellow"/>
    </visual>
  </link>
  <joint name="front_fender_joint" type="fixed">
    <origin rpy="0 0 0" xyz="0 0 0"/>
    <parent link="chassis_link"/>
    <child link="front_fender_link"/>
  </joint>
  <link name="rear_fender_link">
    <visual>
      <geometry>
        <mesh filename="../meshes/jackal-fender.stl"/>
      </geometry>
      <material name="yellow"/>
    </visual>
  </link>
  <joint name="rear_fender_joint" type="fixed">
    <origin rpy="0 0 3.141592653589793" xyz="0 0 0"/>
    <parent link="chassis_link"/>
    <child link="rear_fender_link"/>
  </joint>
  <!-- Default Internal IMU Link -->
  <link name="imu_link">
    <inertial>
      <mass value="0.001"/>
      <origin rpy="0 0 0" xyz="0 0 0"/>
      <inertia ixx="1e-09" ixy="0.0" ixz="0.0" iyy="1e-09" iyz="0.0" izz="1e-09"/>
    </inertial>
  </link>
  <joint name="imu_joint" type="fixed">
    <parent link="chassis_link"/>
    <child link="imu_link"/>
  </joint>
  <!-- Default NAVSAT Link -->
  <link name="navsat_link">
    <visual>
      <geometry>
        <cylinder length="0.016" radius="0.026"/>
      </geometry>
      <origin xyz="0 0 0.008"/>
      <material name="black"/>
    </visual>
  </link>
  <joint name="navsat_joint" type="fixed">
    <parent link="chassis_link"/>
    <child link="navsat_link"/>
    <origin xyz="-0.180 0.126 0.1815"/>
  </joint>
  <link name="mid_mount"/>
  <joint name="mid_mount_joint" type="fixed">
    <parent link="chassis_link"/>
    <child link="mid_mount"/>
    <origin xyz="0 0 0.184"/>
  </joint>
  <link name="rear_mount"/>
  <joint name="rear_mount_joint" type="fixed">
    <parent link="mid_mount"/>
    <child link="rear_mount"/>
    <origin xyz="-0.12 0 0"/>
  </joint>
  <link name="front_mount"/>
  <joint name="front_mount_joint" type="fixed">
    <parent link="mid_mount"/>
    <child link="front_mount"/>
    <origin xyz="0.12 0 0"/>
  </joint>
  <!-- Bring in simulation data for Gazebo. -->
  <!-- <xacro:include filename="jackal.gazebo" /> -->
  <!--
    As you add to this URDF, please be aware that both the robot and
    simulation include it. You must retain compatibility with all of
    the following launch files:

    jackal_viz/launch/view_model.launch
    jackal_gazebo/launch/jackal_world.launch
    jackal_base/launch/base.launch
  -->
  <!-- <xacro:include filename="accessories/hdl32_mount.urdf.xacro" /> -->
  <link name="mid_vlp16_mount"/>
  <link name="mid_vlp16_plate">
    <visual>
      <geometry>
        <box size="0.1 0.1 0.002"/>
      </geometry>
      <material name="black"/>
      <origin rpy="0 0 0" xyz="0 0 -0.001"/>
    </visual>
  </link>
  <link name="mid_vlp16_leg1">
    <visual>
      <geometry>
        <cylinder length="0.1" radius="0.003"/>
      </geometry>
      <material name="white">
        <color rgba="1 1 1 1"/>
      </material>
      <origin rpy="0 0 0" xyz="0 0 0.05"/>
    </visual>
  </link>
  <link name="mid_vlp16_leg2">
    <visual>
      <geometry>
        <cylinder length="0.1" radius="0.003"/>
      </geometry>
      <material name="white">
        <color rgba="1 1 1 1"/>
      </material>
      <origin rpy="0 0 0" xyz="0 0 0.05"/>
    </visual>
  </link>
  <link name="mid_vlp16_leg3">
    <visual>
      <geometry>
        <cylinder length="0.1" radius="0.003"/>
      </geometry>
      <material name="white">
        <color rgba="1 1 1 1"/>
      </material>
      <origin rpy="0 0 0" xyz="0 0 0.05"/>
    </visual>
  </link>
  <link name="mid_vlp16_leg4">
    <visual>
      <geometry>
        <cylinder length="0.1" radius="0.003"/>
      </geometry>
      <material name="white">
        <color rgba="1 1 1 1"/>
      </material>
      <origin rpy="0 0 0" xyz="0 0 0.05"/>
    </visual>
  </link>
  <joint name="mid_vlp16_mount_joint" type="fixed">
    <parent link="mid_mount"/>
    <child link="mid_vlp16_mount"/>
    <origin rpy="0 0 0" xyz="0 0 0"/>
  </joint>
  <joint name="mid_vlp16_leg1_joint" type="fixed">
    <parent link="mid_vlp16_mount"/>
    <child link="mid_vlp16_leg1"/>
    <origin rpy="0 0 0" xyz="0.05 0.05 0"/>
  </joint>
  <joint name="mid_vlp16_leg2_joint" type="fixed">
    <parent link="mid_vlp16_mount"/>
    <child link="mid_vlp16_leg2"/>
    <origin rpy="0 0 0" xyz="0.05 -0.05 0"/>
  </joint>
  <joint name="mid_vlp16_leg3_joint" type="fixed">
    <parent link="mid_vlp16_mount"/>
    <child link="mid_vlp16_leg3"/>
    <origin rpy="0 0 0" xyz="-0.05 0.05 0"/>
  </joint>
  <joint name="mid_vlp16_leg4_joint" type="fixed">
    <parent link="mid_vlp16_mount"/>
    <child link="mid_vlp16_leg4"/>
    <origin rpy="0 0 0" xyz="-0.05 -0.05 0"/>
  </joint>
  <joint name="mid_vlp16_plate_joint" type="fixed">
    <parent link="mid_vlp16_mount"/>
    <child link="mid_vlp16_plate"/>
    <origin rpy="0 0 0" xyz="0 0 0.1"/>
  </joint>
  <joint name="velodyne_base_mount_joint" type="fixed">
    <origin rpy="0 0 0" xyz="0 0 0"/>
    <parent link="mid_vlp16_plate"/>
    <child link="velodyne_base_link"/>
  </joint>
  <link name="velodyne_base_link">
    <inertial>
      <mass value="0.1"/>
      <origin xyz="0 0 0"/>
      <inertia ixx="0.1" ixy="0" ixz="0" iyy="0.1" iyz="0" izz="0.1"/>
    </inertial>
    <visual>
      <geometry>
        <mesh filename="package://velodyne_description/meshes/VLP16_base_1.dae"/>
      </geometry>
    </visual>
    <visual>
      <geometry>
        <mesh filename="package://velodyne_description/meshes/VLP16_base_2.dae"/>
      </geometry>
    </visual>
    <collision>
      <origin rpy="0 0 0" xyz="0 0 0.03585"/>
      <geometry>
        <cylinder length="0.0717" radius="0.0516"/>
      </geometry>
    </collision>
  </link>
  <joint name="velodyne_base_scan_joint" type="fixed">
    <origin rpy="0 0 0" xyz="0 0 0.0377"/>
    <parent link="velodyne_base_link"/>
    <child link="velodyne"/>
  </joint>
  <link name="velodyne">
    <inertial>
      <mass value="0.1"/>
      <origin xyz="0 0 0"/>
      <inertia ixx="0.1" ixy="0" ixz="0" iyy="0.1" iyz="0" izz="0.1"/>
    </inertial>
    <visual>
      <origin xyz="0 0 -0.0377"/>
      <geometry>
        <mesh filename="package://velodyne_description/meshes/VLP16_scan.dae"/>
      </geometry>
    </visual>
  </link>
  <!-- Gazebo requires the velodyne_gazebo_plugins package -->
  <gazebo reference="velodyne">
    <sensor name="velodyne-VLP16" type="ray">
      <pose>0 0 0 0 0 0</pose>
      <visualize>false</visualize>
      <update_rate>10</update_rate>
      <ray>
        <scan>
          <horizontal>
            <samples>1875</samples>
            <resolution>1</resolution>
            <min_angle>-3.141592653589793</min_angle>
            <max_angle>3.141592653589793</max_angle>
          </horizontal>
          <vertical>
            <samples>16</samples>
            <resolution>1</resolution>
            <min_angle>-0.2617993877991494</min_angle>
            <max_angle> 0.2617993877991494</max_angle>
          </vertical>
        </scan>
        <range>
          <min>0.3</min>
          <max>131.0</max>
          <resolution>0.001</resolution>
        </range>
        <noise>
          <type>gaussian</type>
          <mean>0.0</mean>
          <stddev>0.0</stddev>
        </noise>
      </ray>
      <plugin filename="libgazebo_ros_velodyne_laser.so" name="gazebo_ros_laser_controller">
        <topicName>velodyne/mid/points</topicName>
        <frameName>vehicle/velodyne</frameName>
        <min_range>0.9</min_range>
        <max_range>130.0</max_range>
        <gaussianNoise>0.008</gaussianNoise>
      </plugin>
    </sensor>
  </gazebo>
  <!-- 
    Add Cameras. 
    - JACKAL_FLEA3
    - JACKAL_STEREO_FLEA3
    - JACKAL_BB2
  -->
  <!-- Common camera mounts and accessory URDFs. -->
  <!-- <xacro:include filename="accessories/camera_mount.urdf.xacro" /> -->
  <!-- <xacro:include filename="$(find pointgrey_camera_description)/urdf/pointgrey_flea3.urdf.xacro" /> -->
  <!-- If enabled, generate the bumblebee2 camera payload with a tilt of 0 degrees. -->
  <!-- OutdoorNav URDF Config
  <xacro:if value="$(arg outdoornav_enabled)">
    <xacro:include filename="$(find cpr_onav_description)/urdf/outdoornav_description.urdf.xacro" />
    <xacro:outdoornav_sensors outdoornav_configuration="$(arg outdoornav_configuration)" />
  </xacro:if> -->
  <!-- This file is a placeholder which is included by default from
       jackal.urdf.xacro. If a robot is being customized and requires
       additional URDF, set the JACKAL_URDF_EXTRAS environment variable
       to the full path of the file you would like included. -->
  <!-- This file is a placeholder which is included by default from
       jackal.urdf.xacro. If a robot is being customized and requires
       additional URDF, set the JACKAL_URDF_EXTRAS environment variable
       to the full path of the file you would like included. -->
</robot>
